Workbook

Sheet README
B1: SEO COMPETITOR → PAGE SYSTEM
B2: Reverse-engineer the SERP, then build a page that beats it.
B4: HOW TO USE
B5: 1. Give Claude 6–8 competitor URLs (the pages currently ranking for your target query).
B6: 2. Claude fetches each URL IN THE LISTED ORDER and fills one column per link in the »Extraction_Matrix« tab.
B7: 3. Claude runs web searches for the off-page signals (Reddit, YouTube, GBP reviews).
B8: 4. The »Gap_Analysis« tab auto-updates — it scores every feature and the numeric benchmarks across all competitors.
B9: 5. Claude classifies each feature into the 3 tiers and writes your spec into the »Page_Build_Brief« tab.
B10: 6. Ask Claude to draft the page from the brief — written to the 7 standards in the »Writing_Rules« tab.
B11: The page is the SUPERSET: every relevant subtopic any competitor covers (rewritten + improved) PLUS the gaps none of them have.
B12: THE 3-TIER LOGIC (your last 3 requirements)
B13: ✅ MANDATORY — EVERYONE has it → table-stakes. You must match it or you can't compete.
... B29: AI/LLM citation (ChatGPT, AI Overviews, Perplexity). Treated here as a GEO signal, not a Google rich-result play.

Sheet Extraction_Matrix
A1: SEO COMPETITOR EXTRACTION MATRIX
A2: Each link = one column. Claude fills these after fetching the URLs (in order). Binary cells use Y / N.
A3: Source key: P = page fetch · S = web search · J = judgement · M = manual/local
A5: Category | B5: Field / Metric | C5: Src | D5: Link 1 | E5: Link 2 | F5: Link 3 | G5: Link 4 | H5: Link 5 | I5: Link 6 | J5: Link 7 | K5: Link 8 | L5: Pattern / Benchmark
A6: — | B6: URL | C6: M | D6: https://rajputanacabs.in/haridwar/ | E6: https://www.taxiinharidwar.com/ | F6: https://taxiserviceinharidwar.com/ | G6: https://haridwarcarrentals.com/
A7: — | B7: SERP rank / tier (Top / Mid / Low) | C7: S | D7: Top | E7: Top | F7: Mid | G7: Mid | L7: drives the ADVANTAGE tier
A8: A · CORE ON-PAGE
A9: On-page | B9: Title (meta title) | C9: P | D9: Best taxi service in Haridwar at Rs 1600 a day via Rajputana Cabs | E9: Haridwar Taxi Service | Best Cab & Car Rental in Haridwar | F9: Best Taxi Rental Service in Haridwar 2026 | G9: Haridwar Car rentals - Book the Best Car Rental in Haridwar
A10: On-page | B10: Title length (chars) | C10: P | D10: =IF(D9="","",LEN(D9)) | E10: =IF(E9="","",LEN(E9)) | F10: =IF(F9="","",LEN(F9)) | G10: =IF(G9="","",LEN(G9)) | H10: =IF(H9="","",LEN(H9)) | I10: =IF(I9="","",LEN(I9)) | J10: =IF(J9="","",LEN(J9)) | K10: =IF(K9="","",LEN(K9)) | L10: best 50–60
A11: On-page | B11: Meta Description | C11: P | D11: n/a (not exposed in fetch) | E11: n/a (not exposed in fetch) | F11: n/a (not exposed in fetch) | G11: n/a (not exposed in fetch)
A12: On-page | B12: Meta description length (chars) | C12: P | D12: =IF(D11="","",LEN(D11)) | E12: =IF(E11="","",LEN(E11)) | F12: =IF(F11="","",LEN(F11)) | G12: =IF(G11="","",LEN(G11)) | H12: =IF(H11="","",LEN(H11)) | I12: =IF(I11="","",LEN(I11)) | J12: =IF(J11="","",LEN(J11)) | K12: =IF(K11="","",LEN(K11)) | L12: best 140–155
A13: On-page | B13: H1 | C13: P | D13: Best taxi service in Haridwar from Rajputana Cabs | E13: Haridwar Taxi Service | F13: Taxi Service in Haridwar | G13: Haridwar Car Rental
A14: On-page | B14: H2 headings (key ones) | C14: P | D14: Haridwar Cab Fare Chart | Transportation service in Haridwar | One side taxi service from Haridwar | Char Dham Yatra related tours from Haridwar | Haridwar Tourism | FAQ on Taxi service in Haridwar | E14: Haridwar taxi booking | Taxi Services in Haridwar | Rishikesh/Corbett/Kanatal/Chopta/Auli/Nainital/Dehradun/Neelkanth Taxi | 2026 Chardham Yatra Package from Haridwar | Haridwar Taxi Car Rental Types | Swift Dzire / Innova Crysta / Ertiga / Tempo Traveller | Google Customer Reviews | F14: Haridwar/Delhi to Chardham Taxi Service | Best Taxi Service in Uttarakhand | Taxi Rental Service in Haridwar | Car Rental Rates | Our Cars Gallery | Why Choose Taxi service in Haridwar? | What Our Customers Say | FAQs | Approved By | G14: Chardham Yatra Car | Dehradun Airport Car | Best Car Rentals in Haridwar | Car Rental Types | Haridwar Car Rental Services | Quick Enquiry Form | Our Satisfied Customers | Partners & Affiliations
A15: On-page | B15: Word count | C15: P | D15: 3750 | E15: 2300 | F15: 2200 | G15: 1900 | L15: benchmark
A16: On-page | B16: Content Type | C16: J | D16: service | E16: service | F16: service | G16: service | L16: guide/service/blog/product/comparison
A17: On-page | B17: Content FORMAT mix | C17: J | D17: text + lists + one large table + images | E17: text + lists + images; no tables | F17: text + table + large image gallery | G17: text + images + enquiry form; no tables | L17: text / paragraphs / lists / audio / video / images
A18: On-page | B18: Page STRUCTURE | C18: J | D18: table-led service page | E18: listicle service page | F18: table-led service page | G18: listicle service page | L18: listicle / step-by-step / Q&A / narrative / table-led / pillar
A19: On-page | B19: URL Slug | C19: P | D19: /haridwar/ | E19: / | F19: / | G19: /
A20: On-page | B20: URL length (chars) | C20: P | D20: =IF(D6="","",LEN(D6)) | E20: =IF(E6="","",LEN(E6)) | F20: =IF(F6="","",LEN(F6)) | G20: =IF(G6="","",LEN(G6)) | H20: =IF(H6="","",LEN(H6)) | I20: =IF(I6="","",LEN(I6)) | J20: =IF(J6="","",LEN(J6)) | K20: =IF(K6="","",LEN(K6)) | L20: shorter = better
A21: On-page | B21: Keyword in URL? (Y/N) | C21: J | D21: N | E21: N | F21: N | G21: N
A22: On-page | B22: Location in URL? (Y/N) | C22: J | D22: Y | E22: N | F22: N | G22: N
A23: B · TARGETING
A24: Targeting | B24: Target Keyword | C24: J | D24: taxi service in haridwar | E24: haridwar taxi service | F24: taxi service in haridwar | G24: haridwar car rental
A25: Targeting | B25: Location Targeted | C25: J | D25: Haridwar | E25: Haridwar | F25: Haridwar | G25: Haridwar
A26: Targeting | B26: Search Intent | C26: J | D26: transactional | E26: transactional | F26: transactional | G26: transactional | L26: info/commercial/transactional/nav
A27: C · CONTENT RICHNESS
A28: Richness | B28: Unique images (count) | C28: P | D28: 20 | E28: 16 | F28: 30 | G28: 20 | L28: benchmark
A29: Richness | B29: Videos embedded? (Y/N) | C29: P | D29: N | E29: N | F29: N | G29: N
A30: Richness | B30: Maps embedded? (Y/N) | C30: P | D30: N | E30: N | F30: N | G30: N
A31: Richness | B31: Tables used? (Y/N) | C31: P | D31: Y | E31: N | F31: Y | G31: N
A32: Richness | B32: FAQ section present? (Y/N) | C32: P | D32: Y | E32: N | F32: Y | G32: N
A33: Richness | B33: FAQ count (number) | C33: P | D33: 3 | E33: 0 | F33: 6 | G33: 0 | L33: benchmark
A34: Richness | B34: FAQ questions (list) | C34: P | D34: What is the taxi fare for Haridwar to Rishikesh? | Can I get a one side cab for Kedarnath from Haridwar? | What is the cost of Taxi service in Haridwar for Char Dham Yatra? | E34: n/a — no FAQ section | F34: How to book? | Government approved? | Tour packages available? | How to select vehicle? | How to contact? | Payment options? | G34: n/a — no FAQ section
A35: Richness | B35: Internal links (count) | C35: P | D35: 40 | E35: 50 | F35: 15 | G35: 25 | L35: benchmark
A36: Richness | B36: Internal linking STRATEGY | C36: J | D36: Hub-spoke into city + route pages; anchors are route names | E36: Heavy internal linking to destination taxi pages | F36: Shallow — home/about/blog/contact only | G36: Cross-links to their own network of sibling domains | L36: what they link to / anchor style / hub-spoke
A37: Richness | B37: External links (count) | C37: P | D37: 6 | E37: 4 | F37: 3 | G37: 8 | L37: benchmark
A38: D · QUALITY / E-E-A-T / GEO
A39: Quality | B39: FAQ rich / direct answers? (Y/N) | C39: J | D39: Y | E39: N | F39: Y | G39: N | L39: GEO / AI-citation signal
A40: Quality | B40: Conversational writing? (Y/N) | C40: J | D40: N | E40: N | F40: N | G40: N
A41: Quality | B41: Definitions present? (Y/N) | C41: J | D41: N | E41: N | F41: N | G41: N
...

Sheet Gap_Analysis
A1: GAP ANALYSIS — auto-scored from the matrix
A2: Fills itself as the matrix fills. Verdict column tells you which tier each feature is in.
A3: Competitors analysed: | B3: =COUNTA('Extraction_Matrix'!$D$6:$K$6)
A5: PART 1 · BINARY FEATURE GAP (3-TIER)
A6: Feature | B6: # have | C6: of N | D6: % | E6: Verdict | F6: Your move
A7: Videos embedded | B7: =SUMPRODUCT(--(LEFT('Extraction_Matrix'!$D$29:$K$29,1)="Y")) | C7: =COUNTA('Extraction_Matrix'!$D$6:$K$6) | D7: =IF(C7=0,"",B7/C7) | E7: =IF(C7=0,"",IF(B7=C7,"✅ MANDATORY — everyone has it",IF(B7=0,"🚀 OPPORTUNITY — nobody has it","⭐ ADVANTAGE — only some have it")))
A8: Maps embedded | B8: =SUMPRODUCT(--(LEFT('Extraction_Matrix'!$D$30:$K$30,1)="Y")) | C8: =COUNTA('Extraction_Matrix'!$D$6:$K$6) | D8: =IF(C8=0,"",B8/C8) | E8: =IF(C8=0,"",IF(B8=C8,"✅ MANDATORY — everyone has it",IF(B8=0,"🚀 OPPORTUNITY — nobody has it","⭐ ADVANTAGE — only some have it")))
A9: Tables used | B9: =SUMPRODUCT(--(LEFT('Extraction_Matrix'!$D$31:$K$31,1)="Y")) | C9: =COUNTA('Extraction_Matrix'!$D$6:$K$6) | D9: =IF(C9=0,"",B9/C9) | E9: =IF(C9=0,"",IF(B9=C9,"✅ MANDATORY — everyone has it",IF(B9=0,"🚀 OPPORTUNITY — nobody has it","⭐ ADVANTAGE — only some have it")))
A10: FAQ section | B10: =SUMPRODUCT(--(LEFT('Extraction_Matrix'!$D$32:$K$32,1)="Y")) | C10: =COUNTA('Extraction_Matrix'!$D$6:$K$6) | D10: =IF(C10=0,"",B10/C10) | E10: =IF(C10=0,"",IF(B10=C10,"✅ MANDATORY — everyone has it",IF(B10=0,"🚀 OPPORTUNITY — nobody has it","⭐ ADVANTAGE — only some have it")))
A11: FAQ rich/direct answers | B11: =SUMPRODUCT(--(LEFT('Extraction_Matrix'!$D$39:$K$39,1)="Y")) | C11: =COUNTA('Extraction_Matrix'!$D$6:$K$6) | D11: =IF(C11=0,"",B11/C11) | E11: =IF(C11=0,"",IF(B11=C11,"✅ MANDATORY — everyone has it",IF(B11=0,"🚀 OPPORTUNITY — nobody has it","⭐ ADVANTAGE — only some have it")))
A12: Conversational writing | B12: =SUMPRODUCT(--(LEFT('Extraction_Matrix'!$D$40:$K$40,1)="Y")) | C12: =COUNTA('Extraction_Matrix'!$D$6:$K$6) | D12: =IF(C12=0,"",B12/C12) | E12: =IF(C12=0,"",IF(B12=C12,"✅ MANDATORY — everyone has it",IF(B12=0,"🚀 OPPORTUNITY — nobody has it","⭐ ADVANTAGE — only some have it")))
A13: Definitions | B13: =SUMPRODUCT(--(LEFT('Extraction_Matrix'!$D$41:$K$41,1)="Y")) | C13: =COUNTA('Extraction_Matrix'!$D$6:$K$6) | D13: =IF(C13=0,"",B13/C13) | E13: =IF(C13=0,"",IF(B13=C13,"✅ MANDATORY — everyone has it",IF(B13=0,"🚀 OPPORTUNITY — nobody has it","⭐ ADVANTAGE — only some have it")))
A14: Statistics / data cited | B14: =SUMPRODUCT(--(LEFT('Extraction_Matrix'!$D$42:$K$42,1)="Y")) | C14: =COUNTA('Extraction_Matrix'!$D$6:$K$6) | D14: =IF(C14=0,"",B14/C14) | E14: =IF(C14=0,"",IF(B14=C14,"✅ MANDATORY — everyone has it",IF(B14=0,"🚀 OPPORTUNITY — nobody has it","⭐ ADVANTAGE — only some have it")))
A15: Author entity | B15: =SUMPRODUCT(--(LEFT('Extraction_Matrix'!$D$43:$K$43,1)="Y")) | C15: =COUNTA('Extraction_Matrix'!$D$6:$K$6) | D15: =IF(C15=0,"",B15/C15) | E15: =IF(C15=0,"",IF(B15=C15,"✅ MANDATORY — everyone has it",IF(B15=0,"🚀 OPPORTUNITY — nobody has it","⭐ ADVANTAGE — only some have it")))
A16: Citations / sources | B16: =SUMPRODUCT(--(LEFT('Extraction_Matrix'!$D$44:$K$44,1)="Y")) | C16: =COUNTA('Extraction_Matrix'!$D$6:$K$6) | D16: =IF(C16=0,"",B16/C16) | E16: =IF(C16=0,"",IF(B16=C16,"✅ MANDATORY — everyone has it",IF(B16=0,"🚀 OPPORTUNITY — nobody has it","⭐ ADVANTAGE — only some have it")))
A17: Structured data (schema) | B17: =SUMPRODUCT(--(LEFT('Extraction_Matrix'!$D$46:$K$46,1)="Y")) | C17: =COUNTA('Extraction_Matrix'!$D$6:$K$6) | D17: =IF(C17=0,"",B17/C17) | E17: =IF(C17=0,"",IF(B17=C17,"✅ MANDATORY — everyone has it",IF(B17=0,"🚀 OPPORTUNITY — nobody has it","⭐ ADVANTAGE — only some have it")))
A18: Topical authority | B18: =SUMPRODUCT(--(LEFT('Extraction_Matrix'!$D$47:$K$47,1)="Y")) | C18: =COUNTA('Extraction_Matrix'!$D$6:$K$6) | D18: =IF(C18=0,"",B18/C18) | E18: =IF(C18=0,"",IF(B18=C18,"✅ MANDATORY — everyone has it",IF(B18=0,"🚀 OPPORTUNITY — nobody has it","⭐ ADVANTAGE — only some have it")))
A19: Reddit mentions | B19: =SUMPRODUCT(--(LEFT('Extraction_Matrix'!$D$49:$K$49,1)="Y")) | C19: =COUNTA('Extraction_Matrix'!$D$6:$K$6) | D19: =IF(C19=0,"",B19/C19) | E19: =IF(C19=0,"",IF(B19=C19,"✅ MANDATORY — everyone has it",IF(B19=0,"🚀 OPPORTUNITY — nobody has it","⭐ ADVANTAGE — only some have it")))
A20: YouTube presence | B20: =SUMPRODUCT(--(LEFT('Extraction_Matrix'!$D$50:$K$50,1)="Y")) | C20: =COUNTA('Extraction_Matrix'!$D$6:$K$6) | D20: =IF(C20=0,"",B20/C20) | E20: =IF(C20=0,"",IF(B20=C20,"✅ MANDATORY — everyone has it",IF(B20=0,"🚀 OPPORTUNITY — nobody has it","⭐ ADVANTAGE — only some have it")))
A21: GBP reviews (local) | B21: =SUMPRODUCT(--(LEFT('Extraction_Matrix'!$D$52:$K$52,1)="Y")) | C21: =COUNTA('Extraction_Matrix'!$D$6:$K$6) | D21: =IF(C21=0,"",B21/C21) | E21: =IF(C21=0,"",IF(B21=C21,"✅ MANDATORY — everyone has it",IF(B21=0,"🚀 OPPORTUNITY — nobody has it","⭐ ADVANTAGE — only some have it")))
A23: PART 2 · NUMERIC BENCHMARKS (beat the field)
A24: Metric | B24: Min | C24: Avg | D24: Max | E24: Your target | F24: Note
A25: Word count | B25: =IF(COUNT('Extraction_Matrix'!$D$15:$K$15)=0,"",MIN('Extraction_Matrix'!$D$15:$K$15)) | C25: =IF(COUNT('Extraction_Matrix'!$D$15:$K$15)=0,"",ROUND(AVERAGE('Extraction_Matrix'!$D$15:$K$15),0)) | D25: =IF(COUNT('Extraction_Matrix'!$D$15:$K$15)=0,"",MAX('Extraction_Matrix'!$D$15:$K$15)) | F25: aim ≥ Max
A26: Unique images | B26: =IF(COUNT('Extraction_Matrix'!$D$28:$K$28)=0,"",MIN('Extraction_Matrix'!$D$28:$K$28)) | C26: =IF(COUNT('Extraction_Matrix'!$D$28:$K$28)=0,"",ROUND(AVERAGE('Extraction_Matrix'!$D$28:$K$28),0)) | D26: =IF(COUNT('Extraction_Matrix'!$D$28:$K$28)=0,"",MAX('Extraction_Matrix'!$D$28:$K$28)) | F26: ≥ Avg
A27: FAQ count | B27: =IF(COUNT('Extraction_Matrix'!$D$33:$K$33)=0,"",MIN('Extraction_Matrix'!$D$33:$K$33)) | C27: =IF(COUNT('Extraction_Matrix'!$D$33:$K$33)=0,"",ROUND(AVERAGE('Extraction_Matrix'!$D$33:$K$33),0)) | D27: =IF(COUNT('Extraction_Matrix'!$D$33:$K$33)=0,"",MAX('Extraction_Matrix'!$D$33:$K$33)) | F27: ≥ Max
A28: Internal links | B28: =IF(COUNT('Extraction_Matrix'!$D$35:$K$35)=0,"",MIN('Extraction_Matrix'!$D$35:$K$35)) | C28: =IF(COUNT('Extraction_Matrix'!$D$35:$K$35)=0,"",ROUND(AVERAGE('Extraction_Matrix'!$D$35:$K$35),0)) | D28: =IF(COUNT('Extraction_Matrix'!$D$35:$K$35)=0,"",MAX('Extraction_Matrix'!$D$35:$K$35)) | F28: ≥ Avg
A29: External links | B29: =IF(COUNT('Extraction_Matrix'!$D$37:$K$37)=0,"",MIN('Extraction_Matrix'!$D$37:$K$37)) | C29: =IF(COUNT('Extraction_Matrix'!$D$37:$K$37)=0,"",ROUND(AVERAGE('Extraction_Matrix'!$D$37:$K$37),0)) | D29: =IF(COUNT('Extraction_Matrix'!$D$37:$K$37)=0,"",MAX('Extraction_Matrix'!$D$37:$K$37)) | F29: 2–5 authoritative
A31: PART 3 · THE THREE BUCKETS (curated summary)
A32: ✅ MANDATORY (match these) | C32: ⭐ ADVANTAGE (adopt to compete) | E32: 🚀 OPPORTUNITY (your edge)
A33: ↑ pull from Verdict column above

Sheet Page_Build_Brief
B1: PAGE BUILD BRIEF
B2: The spec for the page Claude will build. Targets pull from Gap_Analysis where possible.
A4: PAGE COMPOSITION (what this page IS)
B5: This page = the SUPERSET. It must (a) cover everything relevant that ANY competitor covers — the union of all their subtopics, angles and questions — AND (b) add the OPPORTUNITY gaps none of them have.
B6: Union of coverage: list every distinct H2 / subtopic across all links, dedupe, drop the irrelevant, keep the rest. Each one gets covered — rewritten in our own words and improved, never copied or lightly paraphrased.
B7: Then add the gaps: pull the 🚀 OPPORTUNITY items from Gap_Analysis (and anything obviously missing) so the page answers questions the SERP currently doesn't. That delta is why it out-ranks them.
A8: TARGETING
B9: Target keyword | C9: taxi service in Haridwar
B10: Secondary keywords | C10: haridwar taxi booking, car rental haridwar, haridwar cab rates, tempo traveller haridwar, haridwar local sightseeing taxi
B11: Location | C11: Haridwar, Uttarakhand (Bhupatwala / Har Ki Pauri / Kankhal)
B12: Search intent | C12: Transactional — user wants a rate and a phone number, now
B13: Content type | C13: Local service page
A14: FORMAT & STRUCTURE
B15: Content format mix | C15: Text + rate tables + FAQ + internal route links (no video needed; nobody in the SERP has one) | D15: text/para/list/video/audio/img
B16: Page structure | C16: Table-led service page with a claim-first opening answer | D16: listicle/steps/Q&A/narrative/pillar
A17: ON-PAGE (write these)
B18: Title (≤60 chars) | C18: Taxi Service in Haridwar — Rates from Rs 1,600 | Direct Operator | D18: =IF(C18="","",LEN(C18))
B19: Meta description (≤155) | C19: Book a taxi in Haridwar direct from a local operator since 2010. Fixed 8hr/80km rates, no commission, no surge. Call +91-78179 96730. | D19: =IF(C19="","",LEN(C19))
B20: H1 | C20: Taxi Service in Haridwar — Local Rates, Real Vehicles, No Commission
B21: URL slug | C21: /taxi-service-in-haridwar
A22: H2 OUTLINE
B23: H2 #1 | C23: What a taxi actually costs in Haridwar (rate table, 8hr/80km + per-km)
B24: H2 #2 | C24: Local sightseeing circuits and what they cover
B25: H2 #3 | C25: Airport, railway station and outstation transfers
B26: H2 #4 | C26: Our fleet — what you actually get
B27: H2 #5 | C27: How Haridwar taxi pricing works (hill charges, night charge, driver allowance, parking)
B28: H2 #6 | C28: Booking, payment and cancellation
B29: H2 #7 | C29: How to avoid the common Haridwar taxi scams
B30: H2 #8 | C30: FAQ
A31: TARGETS (from benchmarks)
B32: Word-count target | C32: 1,900-2,400 words (field: 1,900-3,750, avg ~2,540). Beat on usefulness, not length
B33: Internal links (count) | C33: 10-14 internal links
B34: Internal linking plan | C34: Link to /cabs hub, the four dham cab routes, /haridwar-tour-packages, /char-dham-yatra, the new Har Ki Pauri + airport + Rishikesh pages | D34: hub-spoke / anchors / which pages
B35: External links (authoritative) | C35: 3-5: Uttarakhand Transport Dept, IRCTC/Indian Railways, Ganga Sabha, Uttarakhand Tourism
B36: Images / video / maps / tables | C36: Rate tables (mandatory — 2 of 4 have them), 6+ images, no video needed, embedded map optional
A37: REQUIRED FEATURES
B38: ✅ Mandatory (must build) | C38: Rate table, vehicle-type breakdown, testimonials/social proof, prominent phone + WhatsApp CTA
B39: ⭐ Advantage (adopt) | C39: FAQ with direct answers (only 2 of 4 have any FAQ), Char Dham cross-sell, government-approval/trust badge
B40: 🚀 Opportunity (differentiate) | C40: JSON-LD schema of ANY kind (0 of 4 have it) | Named author with a real bio (0 of 4) | Cited primary sources (0 of 4) | Definitions of the pricing terms (0 of 4) | Conversational, non-boilerplate writing (0 of 4) | Scam-avoidance section (0 of 4) | Transparent per-km + extra-charge maths (0 of 4)
A41: FAQ QUESTIONS TO ANSWER
...

Sheet Writing_Rules
B1: WRITING RULES — how the page gets written
B2: The 7 standards every page must pass before it ships. The brief says WHAT to build; this says HOW to write it.
A4: VOICE — NON-NEGOTIABLE (applies to every line on the page)
B5: Personal tone | C5: Write like one knowledgeable person talking to another. Use 'you', and 'I/we' where it fits. Direct address, contractions, the odd aside. Never the detached encyclopedia voice.
B6: Authority | C6: Take a position and commit to it. State things plainly — no hedging stacks ('it could potentially possibly'). Back claims with first-hand specifics, real numbers and named sources, not 'experts say'.
B7: Style | C7: Vary the rhythm — short punchy sentences next to longer ones. Let some personality and mild opinion through. Concrete over abstract. A little mess is human; perfect symmetry reads as machine.
B8: Humanized words | C8: Plain English over AI vocab. Ban: delve, tapestry, underscore, leverage, robust, seamless, testament, pivotal, vibrant, landscape (abstract), 'in the realm of', 'it's important to note', 'let's dive in'. Cut filler and signposting.
B9: The hard rule | C9: If a sentence could have come from any generic AI, rewrite it. After drafting, run the humanizer audit ('what still reads as AI?') and fix every tell. It must not sound AI — strictly. No exceptions.
A11: 1 · SEMANTICS
B12: Do this | C12: Cover the topic as an entity, not just a keyword. Map the related entities, sub-topics and questions a complete page would address (from the H2s across all competitors), then make sure each is genuinely covered. Use semantic HTML — one H1, logical H2/H3 nesting, real lists and tables, descriptive anchor text. Link to your related/cluster pages so the topic reads as a hub.
B13: Watch for | C13: Don't keyword-stuff. Coverage and entity completeness beat repetition. A gap a competitor missed (from Gap_Analysis OPPORTUNITY) is your semantic edge.
A15: 2 · E-E-A-T
B16: Do this | C16: Experience: include first-hand specifics — real examples, numbers, screenshots, things only someone who did it would know. Expertise: name a real author with a bio. Authoritativeness: cite primary sources (studies, official docs, original data) with links. Trust: accurate facts, last-updated date, clear contact/ownership.
B17: Watch for | C17: Vague authority ('experts say') fails E-E-A-T. Attribute to a named, datable source instead.
A19: 3 · HUMANIZER (skill active)
B20: Do this | C20: Run the humanizer pass on the full draft. Strip AI tells: inflated significance ('stands as a testament', 'pivotal moment'), promo language ('nestled', 'vibrant', 'breathtaking'), superficial -ing tails, vague attributions, AI vocab (delve, tapestry, underscore, leverage), em-dash and rule-of-three overuse, filler, hedging, signposting ('let's dive in'), fragmented headers. Then do the final audit: ask 'what still reads as AI?', fix it, and add actual voice — opinions, varied rhythm, specifics.
B21: Watch for | C21: Clean but soulless still fails. Vary sentence length; let a real point of view show.
A23: 4 · SEO-FOCUSED
B24: Do this | C24: Target keyword in: title (≤60 chars), H1, URL slug, first 100 words, and at least one H2 — naturally, not forced. Compelling meta description ≤155 chars. Internal links with descriptive anchors; 2–5 authoritative external links. Hit or beat the word-count / image / FAQ benchmarks from Gap_Analysis. Descriptive image alt text. One clear intent per page.
B25: Watch for | C25: Match the benchmarks, then beat the field on the MANDATORY + ADVANTAGE features.
A27: 5 · SUPER LLM-FRIENDLY (GEO)
B28: Do this | C28: Answer the core question in the first 1–2 sentences, before any wind-up. Write in self-contained, extractable chunks — each section makes sense lifted out of context. Lead sections with the claim, then support it. Include definitions, concrete statistics with sources, and an FAQ with direct answers. Use schema (Article/FAQ/HowTo-equivalent as fits). This is what gets you quoted in AI Overviews, ChatGPT and Perplexity.
B29: Watch for | C29: FAQ schema = a GEO/citation signal (since Aug-2023 it only earns Google rich results for gov/health). Worth it for AI citability, not for Google rich snippets.
A31: 6 · MOBILE RESPONSIVE
B32: Do this | C32: Short paragraphs (2–4 lines). Front-load the point of each section. Scannable subheads, lists and tables instead of walls of text. Tables must reflow / scroll on small screens. Tap targets and buttons sized for thumbs. No layout that needs horizontal scrolling.
B33: Watch for | C33: Most search traffic is mobile and Google indexes mobile-first. If it's painful on a phone, it underperforms.
A35: 7 · YOUR & CHATGPT'S GO-TO RESOURCE
B36: Do this | C36: Aim to be THE page an AI cites when asked about this topic. That means: most complete (covers the OPPORTUNITY gaps nobody else filled), most trustworthy (named author + primary sources), most quotable (clean direct-answer passages), and genuinely original (your own data, examples or angle). If the page only recombines what the competitors already say, it won't be the one that gets referenced.
B37: Watch for | C37: The 3-tier output is the playbook: match MANDATORY, adopt ADVANTAGE, own the OPPORTUNITY.
A39: PRE-PUBLISH CHECKLIST (tick before shipping)
B40: ☐ | C40: Core question answered in first 2 sentences
B41: ☐ | C41: Keyword in title, H1, slug, first 100 words, ≥1 H2
B42: ☐ | C42: Meta ≤155 chars · Title ≤60 chars
B43: ☐ | C43: Word count / images / FAQs meet-or-beat benchmarks
B44: ☐ | C44: Named author + bio present
B45: ☐ | C45: Primary sources cited with links (no 'experts say')
B46: ☐ | C46: All OPPORTUNITY gaps covered
B47: ☐ | C47: Humanizer pass + final anti-AI audit done
B48: ☐ | C48: Internal links (descriptive anchors) + 2–5 external
B49: ☐ | C49: Schema implemented (Article/FAQ as fits)
...
